Workbook

Sheet 5.ID
A1: Do Not Alter or Delete this Worksheet or you submission cannot be graded! | E1: DirVer
A2: Action | B2: Name | C2: Panther ID | D2: Date/Time | E2: S01
A3: Start S01 | B3: Ahadu Solomon | C3: 202020202 | D3: 44459.23 | E3: Microsoft Office User
A4: Starter Sheet | B4: None | C4: 0 | D4: 43831
E5: Welcome to Microsoft Excel version 16.53 build 912 running on Macintosh (Intel) Version 11.2.3 (Build 20D91)!

Sheet Financial information 1 Pt1
A1: Donut Information
A2: Based on the below data, create the profit model for Donuts to Go.
A3: Assume that each customer will buy one donut and one cup of coffee
E5: Row Labels | F5: Sum of Expense/revenue
A6: Item | B6: Profit Model label | C6: Expense/revenue | E6: Fixed Expense | F6: 5800
A7: Revenue: Cup of Coffee | B7: Rev: Coffee | C7: 2.99 | E7: Rev: Coffee | F7: 2.99
A8: Revenue: Donut | B8: Rev: Donut | C8: 2.5 | E8: Rev: Donut | F8: 2.5
A9: Donut ingredients per donunt) | B9: Variable Expense: Donut | C9: 0.5 | E9: Variable Expense: Coffee | F9: 0.5
A10: paper products: napkins, plates etc per Donut | B10: Variable Expense: Donut | C10: 0.1 | E10: Variable Expense: Donut | F10: 0.6
A11: Insurance | B11: Fixed Expense | C11: 300 | E11: Grand Total | F11: 5806.59
A12: Maintenance & Repairs to equipment | B12: Fixed Expense | C12: 0
A13: Marketing & Promotion: Advertising | B13: Fixed Expense | C13: 100
A14: Coffee | B14: Variable Expense: Coffee | C14: 0.35
A15: Coffee cups | B15: Variable Expense: Coffee | C15: 0.15
A16: Payroll: Wages (Owner/ Manager) | B16: Fixed Expense | C16: 2400
A17: Payroll: Wages (per Employees) | B17: Fixed Expense | C17: 1200
A18: Donut and Coffee equipment rent | B18: Fixed Expense | C18: 500
A19: Professional Fees: Accounting | B19: Fixed Expense | C19: 50
A20: Professional Fees: Legal | B20: Fixed Expense | C20: 25
A21: Powdered and Liquid Beverages | B21: Fixed Expense | C21: 0
A22: Rent | B22: Fixed Expense | C22: 1000
A23: Supplies: Office | B23: Fixed Expense | C23: 25
A24: Utilities | B24: Fixed Expense | C24: 200
A29: Additional Data
A30: Operations
A31: Monthly Production | B31: 4000
A32: Lost Sales | B32: 3
A33: Day old revenue | B33: 1.25
A34: High demand, % above Average | B34: 0.22
A35: Low Demand, % below average | B35: 0.26
A36: Franchise Operations
A37: Monthly Fixed Expense increase | B37: 4350
A38: Monthly Production Increase | B38: 0.32
A39: Monthly demand increase | B39: 0.22
A40: States of Natures | B40: probabilities
A41: Low | B41: 0.2
A42: Average demand | B42: 0.55
A43: High | B43: 0.25
A61: Total

Sheet Pivot Table and Chart Pt1
A1: Month | B1: Demand
A2: 43831 | B2: 2395 | D2: Sum of Demand | E2: Column Labels | P2: 1. Copy your data set to columns A and B, leave the labels
A3: 43862 | B3: 2584 | D3: Row Labels | E3: 2020 | F3: 2021 | G3: 2022 | H3: Grand Total | P3: 2. Create a pivot table selecting Existing Worksheet at location D2
A4: 43891 | B4: 2681 | D4: Jan | E4: 2395 | F4: 2434 | G4: 2476 | H4: 7305 | P4: 3. Confirm that there is no data from earlier than Jan 2019, and then remove that line
A5: 43922 | B5: 3002 | D5: Feb | E5: 2584 | F5: 2627 | G5: 3039 | H5: 8250 | P5: 4. Create a Pivot Graph that looks like the one given in the Project instructions on Csepub
A6: 43952 | B6: 3473 | D6: Mar | E6: 2681 | F6: 2710 | G6: 3050 | H6: 8441 | P6: 5. Insert the trend line for 2022 and include the equation
A7: 43983 | B7: 3358 | D7: Apr | E7: 3002 | F7: 2986 | G7: 3431 | H7: 9419
A8: 44013 | B8: 1201 | D8: May | E8: 3473 | F8: 3602 | G8: 3712 | H8: 10787
A9: 44044 | B9: 2549 | D9: Jun | E9: 3358 | F9: 3487 | G9: 3915 | H9: 10760
A10: 44075 | B10: 3012 | D10: Jul | E10: 1201 | F10: 2626 | G10: 2983 | H10: 6810
A11: 44105 | B11: 3561 | D11: Aug | E11: 2549 | F11: 3045 | G11: 3305 | H11: 8899
A12: 44136 | B12: 3432 | D12: Sep | E12: 3012 | F12: 3044 | G12: 3325 | H12: 9381
A13: 44166 | B13: 4515 | D13: Oct | E13: 3561 | F13: 3794 | G13: 4508 | H13: 11863
A14: 44197 | B14: 2434 | D14: Nov | E14: 3432 | F14: 4275 | G14: 4691 | H14: 12398
A15: 44228 | B15: 2627 | D15: Dec | E15: 4515 | F15: 5001 | G15: 6504 | H15: 16020
A16: 44256 | B16: 2710 | D16: Grand Total | E16: 35763 | F16: 39631 | G16: 44939 | H16: 120333
A17: 44287 | B17: 2986
A18: 44317 | B18: 3602
A19: 44348 | B19: 3487
A20: 44378 | B20: 2626
A21: 44409 | B21: 3045
A22: 44440 | B22: 3044
A23: 44470 | B23: 3794
A24: 44501 | B24: 4275
A25: 44531 | B25: 5001
A26: 44562 | B26: 2476
A27: 44593 | B27: 3039
A28: 44621 | B28: 3050
... A37: 44896 | B37: 6504

Sheet SI and regression Pt 2
A1: Month | B1: Demand | C1: Monthly average by Year (demand w/out Seasonality | D1: Seasonal Index | E1: 3 year Average SI | F1: Deseasonalized | G1: Time period | J1: Regression Output
A2: 43831 | B2: 2395 | D2: =B2/$C$13 -> 0.80362386 | E2: =AVERAGE(D2,D14,D26) -> 0.73392853 | F2: =B2/E2 -> 3263.2605 | G2: 1 | I2: CLICK CELL J2 as output cell for regression | J2: SUMMARY OUTPUT
A3: 43862 | B3: 2584 | D3: =B3/$C$13 -> 0.86704136 | E3: =AVERAGE(D3,D15,D27) -> 0.82465977 | F3: =B3/E3 -> 3133.4134 | G3: 2
A4: 43891 | B4: 2681 | D4: =B4/$C$13 -> 0.89958896 | E4: =AVERAGE(D4,D16,D28) -> 0.84486536 | F4: =B4/E4 -> 3173.2867 | G4: 3 | J4: Regression Statistics
A5: 43922 | B5: 3002 | D5: =B5/$C$13 -> 1.007298 | E5: =AVERAGE(D5,D17,D29) -> 0.942538 | F5: =B5/E5 -> 3185.0175 | G5: 4 | J5: Multiple R | K5: 0.68692857
A6: 43952 | B6: 3473 | D6: =B6/$C$13 -> 1.1653385 | E6: =AVERAGE(D6,D18,D30) -> 1.0824034 | F6: =B6/E6 -> 3208.6005 | G6: 5 | J6: R Square | K6: 0.47187086
A7: 43983 | B7: 3358 | D7: =B7/$C$13 -> 1.1267511 | E7: =AVERAGE(D7,D19,D31) -> 1.0760028 | F7: =B7/E7 -> 3120.8098 | G7: 6 | J7: Adjusted R Square | K7: 0.45633765
A8: 44013 | B8: 1201 | D8: =B8/$C$13 -> 0.40298633 | E8: =AVERAGE(D8,D20,D32) -> 0.66488929 | F8: =B8/E8 -> 1806.3157 | G8: 7 | J8: Standard Error | K8: 326.24333
A9: 44044 | B9: 2549 | D9: =B9/$C$13 -> 0.85529737 | E9: =AVERAGE(D9,D21,D33) -> 0.88661084 | F9: =B9/E9 -> 2874.993 | G9: 8 | J9: Observations | K9: 36
A10: 44075 | B10: 3012 | D10: =B10/$C$13 -> 1.0106535 | E10: =AVERAGE(D10,D22,D34) -> 0.94007547 | F10: =B10/E10 -> 3203.9981 | G10: 9
A11: 44105 | B11: 3561 | D11: =B11/$C$13 -> 1.1948662 | E11: =AVERAGE(D11,D23,D35) -> 1.1824763 | F11: =B11/E11 -> 3011.4768 | G11: 10 | J11: ANOVA
A12: 44136 | B12: 3432 | D12: =B12/$C$13 -> 1.1515812 | E12: =AVERAGE(D12,D24,D36) -> 1.2328846 | F12: =B12/E12 -> 2783.7155 | G12: 11 | K12: df | L12: SS | M12: MS | N12: F | O12: Significance F
A13: 44166 | B13: 4515 | C13: =AVERAGE(B2:B13) -> 2980.25 | D13: =B13/$C$13 -> 1.5149736 | E13: =AVERAGE(D13,D25,D37) -> 1.5886657 | F13: =B13/E13 -> 2842.0077 | G13: 12 | J13: Regression | K13: 1 | L13: 3233294.3 | M13: 3233294.3 | N13: 30.378194 | O13: 3.7157457e-06
A14: 44197 | B14: 2434 | D14: =B14/$C$25 -> 0.73699881 | F14: =B14/E2 -> 3316.3992 | G14: 13 | J14: Residual | K14: 34 | L14: 3618780.2 | M14: 106434.71
A15: 44228 | B15: 2627 | D15: =B15/$C$25 -> 0.79543791 | F15: =B15/E3 -> 3185.5562 | G15: 14 | J15: Total | K15: 35 | L15: 6852074.4
A16: 44256 | B16: 2710 | D16: =B16/$C$25 -> 0.82056976 | F16: =B16/E4 -> 3207.6117 | G16: 15
A17: 44287 | B17: 2986 | D17: =B17/$C$25 -> 0.9041407 | F17: =B17/E5 -> 3168.042 | G17: 16 | K17: Coefficients | L17: Standard Error | M17: t Stat | N17: P-value | O17: Lower 95% | P17: Upper 95% | Q17: Lower 95.0% | R17: Upper 95.0%
A18: 44317 | B18: 3602 | D18: =B18/$C$25 -> 1.0906614 | F18: =B18/E6 -> 3327.7797 | G18: 17 | J18: Intercept | K18: 2809.0229 | L18: 111.05364 | M18: 25.294289 | N18: 1.2408381e-23 | O18: 2583.3347 | P18: 3034.711 | Q18: 2583.3347 | R18: 3034.711
A19: 44348 | B19: 3487 | D19: =B19/$C$25 -> 1.0558401 | F19: =B19/E7 -> 3240.6979 | G19: 18 | J19: Time period | K19: 28.848757 | L19: 5.2341496 | M19: 5.5116417 | N19: 3.7157457e-06 | O19: 18.211685 | P19: 39.485829 | Q19: 18.211685 | R19: 39.485829
A20: 44378 | B20: 2626 | D20: =B20/$C$25 -> 0.79513512 | F20: =B20/E8 -> 3949.5297 | G20: 19
A21: 44409 | B21: 3045 | D21: =B21/$C$25 -> 0.9220055 | F21: =B21/E9 -> 3434.4268 | G21: 20
A22: 44440 | B22: 3044 | D22: =B22/$C$25 -> 0.92170271 | F22: =B22/E10 -> 3238.0379 | G22: 21
A23: 44470 | B23: 3794 | D23: =B23/$C$25 -> 1.1487977 | F23: =B23/E11 -> 3208.5209 | G23: 22
A24: 44501 | B24: 4275 | D24: =B24/$C$25 -> 1.2944412 | F24: =B24/E12 -> 3467.4778 | G24: 23
A25: 44531 | B25: 5001 | C25: =AVERAGE(B14:B25) -> 3302.5833 | D25: =B25/$C$25 -> 1.5142691 | F25: =B25/E13 -> 3147.9248 | G25: 24
A26: 44562 | B26: 2476 | D26: =B26/$C$37 -> 0.66116291 | F26: =B26/E2 -> 3373.6255 | G26: 25
A27: 44593 | B27: 3039 | D27: =B27/$C$37 -> 0.81150003 | F27: =B27/E3 -> 3685.1561 | G27: 26
A28: 44621 | B28: 3050 | D28: =B28/$C$37 -> 0.81443735 | F28: =B28/E4 -> 3610.0427 | G28: 27
A29: 44652 | B29: 3431 | D29: =B29/$C$37 -> 0.91617526 | F29: =B29/E5 -> 3640.1715 | G29: 28
A30: 44682 | B30: 3712 | D30: =B30/$C$37 -> 0.99121031 | F30: =B30/E6 -> 3429.4054 | G30: 29
A31: 44713 | B31: 3915 | D31: =B31/$C$37 -> 1.0454171 | F31: =B31/E7 -> 3638.4664 | G31: 30
A32: 44743 | B32: 2983 | D32: =B32/$C$37 -> 0.79654643 | F32: =B32/E8 -> 4486.4612 | G32: 31
A33: 44774 | B33: 3305 | D33: =B33/$C$37 -> 0.88252965 | F33: =B33/E9 -> 3727.6783 | G33: 32
A34: 44805 | B34: 3325 | D34: =B34/$C$37 -> 0.88787022 | F34: =B34/E10 -> 3536.9501 | G34: 33
A35: 44835 | B35: 4508 | D35: =B35/$C$37 -> 1.2037651 | F35: =B35/E11 -> 3812.3385 | G35: 34
A36: 44866 | B36: 4691 | D36: =B36/$C$37 -> 1.2526313 | F36: =B36/E12 -> 3804.8979 | G36: 35 | H36: The below 2 columns are for the forecast for 2023
A37: 44896 | B37: 6504 | C37: =AVERAGE(B26:B37) -> 3744.9167 | D37: =B37/$C$37 -> 1.7367543 | F37: =B37/E13 -> 4094.0018 | G37: 36 | H37: Deseasonalized forecast | I37: Seasonalized forecast, Use the average seasonal Index
B38: This space will be left blank. | G38: 37 | H38: =$K$19*G38+$K$18 -> 3876.4269 | I38: =H38*E2 -> 2845.0203
G39: 38 | H39: =$K$19*G39+$K$18 -> 3905.2756 | I39: =H39*E3 -> 3220.5237
B40: For the C and E columns above, only the blue boxes are needed | G40: 39 | H40: =$K$19*G40+$K$18 -> 3934.1244 | I40: =H40*E4 -> 3323.8054
...

Sheet Current operations  Pt3 
A1: CURRENT OPERATIONS | B1: Reminder: Format Cells to show 2 decimal places | E1: Monthly Production | F1: Lost Sales | G1: Day old revenue | Z1: Fall 25
E2: 4000 | F2: 3 | G2: 1.25
A3: AVERAGE DEMAND
A4: Month | B4: 44927 | C4: 44958 | D4: 44986 | E4: 45017 | F4: 45047 | G4: 45078 | H4: 45108 | I4: 45139 | J4: 45170 | K4: 45200 | L4: 45231 | M4: 45261 | N4: Yearly Total
A5: Demand | B5: ='SI and regression Pt 2'!I38 -> 2845.0203 | C5: ='SI and regression Pt 2'!I39 -> 3220.5237 | D5: ='SI and regression Pt 2'!I40 -> 3323.8054 | E5: ='SI and regression Pt 2'!I41 -> 3735.2528 | F5: ='SI and regression Pt 2'!I42 -> 4320.7615 | G5: ='SI and regression Pt 2'!I43 -> 4326.2528 | H5: ='SI and regression Pt 2'!I44 -> 2692.4821 | I5: ='SI and regression Pt 2'!I45 -> 3615.9254 | J5: ='SI and regression Pt 2'!I46 -> 3861.0939 | K5: ='SI and regression Pt 2'!I47 -> 4890.7997 | L5: ='SI and regression Pt 2'!I48 -> 5134.8589 | M5: ='SI and regression Pt 2'!I49 -> 6662.4876 | N5: =SUM(B5:M5) -> 48629.264
A6: satisfied demand | B6: =MIN(B5,$E$2) -> 2845.0203 | C6: =MIN(C5,$E$2) -> 3220.5237 | D6: =MIN(D5,$E$2) -> 3323.8054 | E6: =MIN(E5,$E$2) -> 3735.2528 | F6: =MIN(F5,$E$2) -> 4000 | G6: =MIN(G5,$E$2) -> 4000 | H6: =MIN(H5,$E$2) -> 2692.4821 | I6: =MIN(I5,$E$2) -> 3615.9254 | ... M6: =MIN(M5,$E$2) -> 4000 | N6: =SUM(B6:M6) -> 43294.104
A7: Extra donuts(over) | B7: =IF($E$2>B5, $E$2-B5, 0) -> 1154.9797 | C7: =IF($E$2>C5, $E$2-C5, 0) -> 779.47631 | D7: =IF($E$2>D5, $E$2-D5, 0) -> 676.1946 | E7: =IF($E$2>E5, $E$2-E5, 0) -> 264.74722 | F7: =IF($E$2>F5, $E$2-F5, 0) -> 0 | G7: =IF($E$2>G5, $E$2-G5, 0) -> 0 | H7: =IF($E$2>H5, $E$2-H5, 0) -> 1307.5179 | I7: =IF($E$2>I5, $E$2-I5, 0) -> 384.07456 | ... M7: =IF($E$2>M5, $E$2-M5, 0) -> 0 | N7: =SUM(B7:M7) -> 4705.8965
A8: Unsatisfied customers (short) | B8: =IF(B5>$E$2, B5-$E$2, 0) -> 0 | C8: =IF(C5>$E$2, C5-$E$2, 0) -> 0 | D8: =IF(D5>$E$2, D5-$E$2, 0) -> 0 | E8: =IF(E5>$E$2, E5-$E$2, 0) -> 0 | F8: =IF(F5>$E$2, F5-$E$2, 0) -> 320.76151 | G8: =IF(G5>$E$2, G5-$E$2, 0) -> 326.25283 | H8: =IF(H5>$E$2, H5-$E$2, 0) -> 0 | I8: =IF(I5>$E$2, I5-$E$2, 0) -> 0 | ... M8: =IF(M5>$E$2, M5-$E$2, 0) -> 2662.4876 | N8: =SUM(B8:M8) -> 5335.1605
A9: Revenue
A10: coffee | B10: =B6*2.99 -> 8506.6106 | C10: =C6*2.99 -> 9629.3658 | D10: =D6*2.99 -> 9938.1781 | E10: =E6*2.99 -> 11168.406 | F10: =F6*2.99 -> 11960 | G10: =G6*2.99 -> 11960 | H10: =H6*2.99 -> 8050.5215 | I10: =I6*2.99 -> 10811.617 | ... M10: =M6*2.99 -> 11960 | N10: =SUM(B10:M10) -> 129449.37
A11: donut | B11: =B6*2.5 -> 7112.5507 | C11: =C6*2.5 -> 8051.3092 | D11: =D6*2.5 -> 8309.5135 | E11: =E6*2.5 -> 9338.132 | F11: =F6*2.5 -> 10000 | G11: =G6*2.5 -> 10000 | H11: =H6*2.5 -> 6731.2052 | I11: =I6*2.5 -> 9039.8136 | ... M11: =M6*2.5 -> 10000 | N11: =SUM(B11:M11) -> 108235.26
A12: Revenue from day old sales | B12: =B7*$G$2 -> 1443.7247 | C12: =C7*$G$2 -> 974.34538 | D12: =D7*$G$2 -> 845.24326 | E12: =E7*$G$2 -> 330.93402 | F12: =F7*$G$2 -> 0 | G12: =G7*$G$2 -> 0 | H12: =H7*$G$2 -> 1634.3974 | I12: =I7*$G$2 -> 480.0932 | ... M12: =M7*$G$2 -> 0 | N12: =SUM(B12:M12) -> 5882.3706
A13: Total Revenue | B13: =SUM(B10:B12) -> 17062.886 | C13: =SUM(C10:C12) -> 18655.02 | D13: =SUM(D10:D12) -> 19092.935 | E13: =SUM(E10:E12) -> 20837.472 | F13: =SUM(F10:F12) -> 21960 | G13: =SUM(G10:G12) -> 21960 | H13: =SUM(H10:H12) -> 16416.124 | I13: =SUM(I10:I12) -> 20331.524 | ... M13: =SUM(M10:M12) -> 21960 | N13: =SUM(B13:M13) -> 243567
A14: Expenses
A15: Fixed Expenses | B15: 5800 | C15: 5800 | D15: 5800 | E15: 5800 | F15: 5800 | G15: 5800 | H15: 5800 | I15: 5800 | J15: 5800 | K15: 5800 | L15: 5800 | M15: 5800 | N15: =SUM(B15:M15) -> 69600
A16: Total Fixed Expense | B16: 5800 | C16: 5800 | D16: 5800 | E16: 5800 | F16: 5800 | G16: 5800 | H16: 5800 | I16: 5800 | J16: 5800 | K16: 5800 | L16: 5800 | M16: 5800 | N16: =SUM(B16:M16) -> 69600
A18: Variable Expenses
A19: Coffee Variable expense | B19: =$E$2*0.5 -> 2000 | C19: =$E$2*0.5 -> 2000 | D19: =$E$2*0.5 -> 2000 | E19: =$E$2*0.5 -> 2000 | F19: =$E$2*0.5 -> 2000 | G19: =$E$2*0.5 -> 2000 | H19: =$E$2*0.5 -> 2000 | I19: =$E$2*0.5 -> 2000 | ... M19: =$E$2*0.5 -> 2000 | N19: =SUM(B19:M19) -> 24000
A20: Donut Variable expense | B20: =$E$2*0.6 -> 2400 | C20: =$E$2*0.6 -> 2400 | D20: =$E$2*0.6 -> 2400 | E20: =$E$2*0.6 -> 2400 | F20: =$E$2*0.6 -> 2400 | G20: =$E$2*0.6 -> 2400 | H20: =$E$2*0.6 -> 2400 | I20: =$E$2*0.6 -> 2400 | ... M20: =$E$2*0.6 -> 2400 | N20: =SUM(B20:M20) -> 28800
A21: Total Variable Expenses | B21: =SUM(B19,B20) -> 4400 | C21: =SUM(C19,C20) -> 4400 | D21: =SUM(D19,D20) -> 4400 | E21: =SUM(E19,E20) -> 4400 | F21: =SUM(F19,F20) -> 4400 | G21: =SUM(G19,G20) -> 4400 | H21: =SUM(H19,H20) -> 4400 | I21: =SUM(I19,I20) -> 4400 | ... M21: =SUM(M19,M20) -> 4400 | N21: =SUM(B21:M21) -> 52800
A22: Expenses: due to lost sales | B22: =B8*$F$2 -> 0 | C22: =C8*$F$2 -> 0 | D22: =D8*$F$2 -> 0 | E22: =E8*$F$2 -> 0 | F22: =F8*$F$2 -> 962.28453 | G22: =G8*$F$2 -> 978.75848 | H22: =H8*$F$2 -> 0 | I22: =I8*$F$2 -> 0 | ... M22: =M8*$F$2 -> 7987.4627 | N22: =SUM(B22:M22) -> 16005.482
A23: Total Expenses | B23: =SUM(B16,B21,B22) -> 10200 | C23: =SUM(C16,C21,C22) -> 10200 | D23: =SUM(D16,D21,D22) -> 10200 | E23: =SUM(E16,E21,E22) -> 10200 | F23: =SUM(F16,F21,F22) -> 11162.285 | G23: =SUM(G16,G21,G22) -> 11178.758 | H23: =SUM(H16,H21,H22) -> 10200 | I23: =SUM(I16,I21,I22) -> 10200 | ... M23: =SUM(M16,M21,M22) -> 18187.463 | N23: =SUM(B23:M23) -> 138405.48
A25: Profit Donuts and Coffee | B25: =B13-B23 -> 6862.8859 | C25: =C13-C23 -> 8455.0205 | D25: =D13-D23 -> 8892.9349 | E25: =E13-E23 -> 10637.472 | F25: =F13-F23 -> 10797.715 | G25: =G13-G23 -> 10781.242 | H25: =H13-H23 -> 6216.1241 | I25: =I13-I23 -> 10131.524 | ... M25: =M13-M23 -> 3772.5373 | N25: =SUM(B25:M25) -> 105161.52
B27: You should be able to copy from average to high and low and then just make some modifications
A28: HIGH DEMAND
A29: Month | B29: =B4 -> 44927 | C29: =C4 -> 44958 | D29: =D4 -> 44986 | E29: =E4 -> 45017 | F29: =F4 -> 45047 | G29: =G4 -> 45078 | H29: =H4 -> 45108 | I29: =I4 -> 45139 | ... M29: =M4 -> 45261 | N29: Yearly Total
A30: Demand | B30: =B5*1.22 -> 3470.9247 | C30: =C5*1.22 -> 3929.0389 | D30: =D5*1.22 -> 4055.0426 | E30: =E5*1.22 -> 4557.0084 | F30: =F5*1.22 -> 5271.329 | G30: =G5*1.22 -> 5278.0284 | H30: =H5*1.22 -> 3284.8282 | I30: =I5*1.22 -> 4411.429 | ... M30: =M5*1.22 -> 8128.2348 | N30: =SUM(B30:M30) -> 59327.702
A31: satisfied demand | B31: =MIN(B30,$E$2) -> 3470.9247 | C31: =MIN(C30,$E$2) -> 3929.0389 | D31: =MIN(D30,$E$2) -> 4000 | E31: =MIN(E30,$E$2) -> 4000 | F31: =MIN(F30,$E$2) -> 4000 | G31: =MIN(G30,$E$2) -> 4000 | H31: =MIN(H30,$E$2) -> 3284.8282 | I31: =MIN(I30,$E$2) -> 4000 | ... M31: =MIN(M30,$E$2) -> 4000 | N31: =SUM(B31:M31) -> 46684.792
A32: Extra donuts(over) | B32: =IF($E$2>B30, $E$2-B30, 0) -> 529.07528 | C32: =IF($E$2>C30, $E$2-C30, 0) -> 70.961094 | D32: =IF($E$2>D30, $E$2-D30, 0) -> 0 | E32: =IF($E$2>E30, $E$2-E30, 0) -> 0 | F32: =IF($E$2>F30, $E$2-F30, 0) -> 0 | G32: =IF($E$2>G30, $E$2-G30, 0) -> 0 | H32: =IF($E$2>H30, $E$2-H30, 0) -> 715.17184 | I32: =IF($E$2>I30, $E$2-I30, 0) -> 0 | ... M32: =IF($E$2>M30, $E$2-M30, 0) -> 0 | N32: =SUM(B32:M32) -> 1315.2082
A33: Unsatisfied customers (short) | B33: =IF(B30>$E$2, B30-$E$2, 0) -> 0 | C33: =IF(C30>$E$2, C30-$E$2, 0) -> 0 | D33: =IF(D30>$E$2, D30-$E$2, 0) -> 55.042582 | E33: =IF(E30>$E$2, E30-$E$2, 0) -> 557.0084 | F33: =IF(F30>$E$2, F30-$E$2, 0) -> 1271.329 | G33: =IF(G30>$E$2, G30-$E$2, 0) -> 1278.0284 | H33: =IF(H30>$E$2, H30-$E$2, 0) -> 0 | I33: =IF(I30>$E$2, I30-$E$2, 0) -> 411.42903 | ... M33: =IF(M30>$E$2, M30-$E$2, 0) -> 4128.2348 | N33: =SUM(B33:M33) -> 12642.91
A34: Revenue
A35: coffee | B35: =B31*2.99 -> 10378.065 | C35: =C31*2.99 -> 11747.826 | D35: =D31*2.99 -> 11960 | E35: =E31*2.99 -> 11960 | F35: =F31*2.99 -> 11960 | G35: =G31*2.99 -> 11960 | H35: =H31*2.99 -> 9821.6362 | I35: =I31*2.99 -> 11960 | ... M35: =M31*2.99 -> 11960 | N35: =SUM(B35:M35) -> 139587.53
A36: donut | B36: =B31*2.5 -> 8677.3118 | C36: =C31*2.5 -> 9822.5973 | D36: =D31*2.5 -> 10000 | E36: =E31*2.5 -> 10000 | F36: =F31*2.5 -> 10000 | G36: =G31*2.5 -> 10000 | H36: =H31*2.5 -> 8212.0704 | I36: =I31*2.5 -> 10000 | ... M36: =M31*2.5 -> 10000 | N36: =SUM(B36:M36) -> 116711.98
A37: Revenue from day old sales | B37: =B32*$G$2 -> 661.3441 | C37: =C32*$G$2 -> 88.701368 | D37: =D32*$G$2 -> 0 | E37: =E32*$G$2 -> 0 | F37: =F32*$G$2 -> 0 | G37: =G32*$G$2 -> 0 | H37: =H32*$G$2 -> 893.9648 | I37: =I32*$G$2 -> 0 | ... M37: =M32*$G$2 -> 0 | N37: =SUM(B37:M37) -> 1644.0103
A38: Total Revenue | B38: =SUM(B35:B37) -> 19716.721 | C38: =SUM(C35:C37) -> 21659.125 | D38: =SUM(D35:D37) -> 21960 | E38: =SUM(E35:E37) -> 21960 | F38: =SUM(F35:F37) -> 21960 | G38: =SUM(G35:G37) -> 21960 | H38: =SUM(H35:H37) -> 18927.671 | I38: =SUM(I35:I37) -> 21960 | ... M38: =SUM(M35:M37) -> 21960 | N38: =SUM(B38:M38) -> 257943.52
A39: Expenses
A40: Fixed Expenses | B40: 5800 | C40: 5800 | D40: 5800 | E40: 5800 | F40: 5800 | G40: 5800 | H40: 5800 | I40: 5800 | J40: 5800 | K40: 5800 | L40: 5800 | M40: 5800 | N40: =SUM(B40:M40) -> 69600
A41: Total Fixed Expense | B41: 5800 | C41: 5800 | D41: 5800 | E41: 5800 | F41: 5800 | G41: 5800 | H41: 5800 | I41: 5800 | J41: 5800 | K41: 5800 | L41: 5800 | M41: 5800 | N41: =SUM(B41:M41) -> 69600
A43: Variable Expenses
A44: Coffee Variable expense | B44: =$E$2*0.5 -> 2000 | C44: =$E$2*0.5 -> 2000 | D44: =$E$2*0.5 -> 2000 | E44: =$E$2*0.5 -> 2000 | F44: =$E$2*0.5 -> 2000 | G44: =$E$2*0.5 -> 2000 | H44: =$E$2*0.5 -> 2000 | I44: =$E$2*0.5 -> 2000 | ... M44: =$E$2*0.5 -> 2000 | N44: =SUM(B44:M44) -> 24000
...

Sheet Franchise operations  Pt3
A1: FRANCHISE | B1: Reminder: Format Cells to show 2 decimal places | E1: Monthly Production | F1: Lost Sales | G1: Day old revenue
E2: =4000*1.32 -> 5280 | F2: 3 | G2: 1.25
A3: AVERAGE DEMAND
A4: Month | B4: 44927 | C4: 44958 | D4: 44986 | E4: 45017 | F4: 45047 | G4: 45078 | H4: 45108 | I4: 45139 | J4: 45170 | K4: 45200 | L4: 45231 | M4: 45261 | N4: Yearly Total
A5: Demand | B5: ='SI and regression Pt 2'!I38*1.22 -> 3470.9247 | C5: ='SI and regression Pt 2'!I39*1.22 -> 3929.0389 | D5: ='SI and regression Pt 2'!I40*1.22 -> 4055.0426 | E5: ='SI and regression Pt 2'!I41*1.22 -> 4557.0084 | F5: ='SI and regression Pt 2'!I42*1.22 -> 5271.329 | G5: ='SI and regression Pt 2'!I43*1.22 -> 5278.0284 | H5: ='SI and regression Pt 2'!I44*1.22 -> 3284.8282 | I5: ='SI and regression Pt 2'!I45*1.22 -> 4411.429 | J5: ='SI and regression Pt 2'!I46*1.22 -> 4710.5345 | K5: ='SI and regression Pt 2'!I47*1.22 -> 5966.7757 | L5: ='SI and regression Pt 2'!I48*1.22 -> 6264.5278 | M5: ='SI and regression Pt 2'!I49*1.22 -> 8128.2348 | N5: =SUM(B5:M5) -> 59327.702
A6: satisfied demand | B6: =MIN(B5,$E$2) -> 3470.9247 | C6: =MIN(C5,$E$2) -> 3929.0389 | D6: =MIN(D5,$E$2) -> 4055.0426 | E6: =MIN(E5,$E$2) -> 4557.0084 | F6: =MIN(F5,$E$2) -> 5271.329 | G6: =MIN(G5,$E$2) -> 5278.0284 | H6: =MIN(H5,$E$2) -> 3284.8282 | I6: =MIN(I5,$E$2) -> 4411.429 | ... M6: =MIN(M5,$E$2) -> 5280 | N6: =SUM(B6:M6) -> 54808.164
A7: Extra donuts(over) | B7: =IF($E$2>B5, $E$2-B5, 0) -> 1809.0753 | C7: =IF($E$2>C5, $E$2-C5, 0) -> 1350.9611 | D7: =IF($E$2>D5, $E$2-D5, 0) -> 1224.9574 | E7: =IF($E$2>E5, $E$2-E5, 0) -> 722.9916 | F7: =IF($E$2>F5, $E$2-F5, 0) -> 8.6709565 | G7: =IF($E$2>G5, $E$2-G5, 0) -> 1.9715515 | H7: =IF($E$2>H5, $E$2-H5, 0) -> 1995.1718 | I7: =IF($E$2>I5, $E$2-I5, 0) -> 868.57097 | ... M7: =IF($E$2>M5, $E$2-M5, 0) -> 0 | N7: =SUM(B7:M7) -> 8551.8362
A8: Unsatisfied customers (short) | B8: =IF(B5>$E$2, B5-$E$2, 0) -> 0 | C8: =IF(C5>$E$2, C5-$E$2, 0) -> 0 | D8: =IF(D5>$E$2, D5-$E$2, 0) -> 0 | E8: =IF(E5>$E$2, E5-$E$2, 0) -> 0 | F8: =IF(F5>$E$2, F5-$E$2, 0) -> 0 | G8: =IF(G5>$E$2, G5-$E$2, 0) -> 0 | H8: =IF(H5>$E$2, H5-$E$2, 0) -> 0 | I8: =IF(I5>$E$2, I5-$E$2, 0) -> 0 | ... M8: =IF(M5>$E$2, M5-$E$2, 0) -> 2848.2348 | N8: =SUM(B8:M8) -> 4519.5384
A9: Revenue
A10: coffee | B10: =B6*2.99 -> 10378.065 | C10: =C6*2.99 -> 11747.826 | D10: =D6*2.99 -> 12124.577 | E10: =E6*2.99 -> 13625.455 | F10: =F6*2.99 -> 15761.274 | G10: =G6*2.99 -> 15781.305 | H10: =H6*2.99 -> 9821.6362 | I10: =I6*2.99 -> 13190.173 | ... M10: =M6*2.99 -> 15787.2 | N10: =SUM(B10:M10) -> 163876.41
A11: donut | B11: =B6*2.5 -> 8677.3118 | C11: =C6*2.5 -> 9822.5973 | D11: =D6*2.5 -> 10137.606 | E11: =E6*2.5 -> 11392.521 | F11: =F6*2.5 -> 13178.323 | G11: =G6*2.5 -> 13195.071 | H11: =H6*2.5 -> 8212.0704 | I11: =I6*2.5 -> 11028.573 | ... M11: =M6*2.5 -> 13200 | N11: =SUM(B11:M11) -> 137020.41
A12: Revenue from day old sales | B12: =B7*$G$2 -> 2261.3441 | C12: =C7*$G$2 -> 1688.7014 | D12: =D7*$G$2 -> 1531.1968 | E12: =E7*$G$2 -> 903.73951 | F12: =F7*$G$2 -> 10.838696 | G12: =G7*$G$2 -> 2.4644394 | H12: =H7*$G$2 -> 2493.9648 | I12: =I7*$G$2 -> 1085.7137 | ... M12: =M7*$G$2 -> 0 | N12: =SUM(B12:M12) -> 10689.795
A13: Total Revenue | B13: =SUM(B10:B12) -> 21316.721 | C13: =SUM(C10:C12) -> 23259.125 | D13: =SUM(D10:D12) -> 23793.381 | E13: =SUM(E10:E12) -> 25921.716 | F13: =SUM(F10:F12) -> 28950.435 | G13: =SUM(G10:G12) -> 28978.841 | H13: =SUM(H10:H12) -> 20527.671 | I13: =SUM(I10:I12) -> 25304.459 | ... M13: =SUM(M10:M12) -> 28987.2 | N13: =SUM(B13:M13) -> 311586.61
A14: Expenses
A15: Fixed Expenses | B15: =5800+4350 -> 10150 | C15: =5800+4350 -> 10150 | D15: =5800+4350 -> 10150 | E15: =5800+4350 -> 10150 | F15: =5800+4350 -> 10150 | G15: =5800+4350 -> 10150 | H15: =5800+4350 -> 10150 | I15: =5800+4350 -> 10150 | ... M15: =5800+4350 -> 10150 | N15: =SUM(B15:M15) -> 121800
A16: Total Fixed Expense | B16: =5800+4350 -> 10150 | C16: =5800+4350 -> 10150 | D16: =5800+4350 -> 10150 | E16: =5800+4350 -> 10150 | F16: =5800+4350 -> 10150 | G16: =5800+4350 -> 10150 | H16: =5800+4350 -> 10150 | I16: =5800+4350 -> 10150 | ... M16: =5800+4350 -> 10150 | N16: =SUM(B16:M16) -> 121800
A18: Variable Expenses
A19: Coffee Variable expense | B19: =$E$2*0.5 -> 2640 | C19: =$E$2*0.5 -> 2640 | D19: =$E$2*0.5 -> 2640 | E19: =$E$2*0.5 -> 2640 | F19: =$E$2*0.5 -> 2640 | G19: =$E$2*0.5 -> 2640 | H19: =$E$2*0.5 -> 2640 | I19: =$E$2*0.5 -> 2640 | ... M19: =$E$2*0.5 -> 2640 | N19: =SUM(B19:M19) -> 31680
A20: Donut Variable expense | B20: =$E$2*0.6 -> 3168 | C20: =$E$2*0.6 -> 3168 | D20: =$E$2*0.6 -> 3168 | E20: =$E$2*0.6 -> 3168 | F20: =$E$2*0.6 -> 3168 | G20: =$E$2*0.6 -> 3168 | H20: =$E$2*0.6 -> 3168 | I20: =$E$2*0.6 -> 3168 | ... M20: =$E$2*0.6 -> 3168 | N20: =SUM(B20:M20) -> 38016
A21: Total Variable Expenses | B21: =SUM(B19,B20) -> 5808 | C21: =SUM(C19,C20) -> 5808 | D21: =SUM(D19,D20) -> 5808 | E21: =SUM(E19,E20) -> 5808 | F21: =SUM(F19,F20) -> 5808 | G21: =SUM(G19,G20) -> 5808 | H21: =SUM(H19,H20) -> 5808 | I21: =SUM(I19,I20) -> 5808 | ... M21: =SUM(M19,M20) -> 5808 | N21: =SUM(B21:M21) -> 69696
A22: Expenses: due to lost sales | B22: =B8*$F$2 -> 0 | C22: =C8*$F$2 -> 0 | D22: =D8*$F$2 -> 0 | E22: =E8*$F$2 -> 0 | F22: =F8*$F$2 -> 0 | G22: =G8*$F$2 -> 0 | H22: =H8*$F$2 -> 0 | I22: =I8*$F$2 -> 0 | ... M22: =M8*$F$2 -> 8544.7045 | N22: =SUM(B22:M22) -> 13558.615
A23: Total Expenses | B23: =SUM(B16,B21,B22) -> 15958 | C23: =SUM(C16,C21,C22) -> 15958 | D23: =SUM(D16,D21,D22) -> 15958 | E23: =SUM(E16,E21,E22) -> 15958 | F23: =SUM(F16,F21,F22) -> 15958 | G23: =SUM(G16,G21,G22) -> 15958 | H23: =SUM(H16,H21,H22) -> 15958 | I23: =SUM(I16,I21,I22) -> 15958 | ... M23: =SUM(M16,M21,M22) -> 24502.705 | N23: =SUM(B23:M23) -> 205054.62
A25: Profit Donuts and Coffee | B25: =B13-B23 -> 5358.7208 | C25: =C13-C23 -> 7301.125 | D25: =D13-D23 -> 7835.3805 | E25: =E13-E23 -> 9963.7156 | F25: =F13-F23 -> 12992.435 | G25: =G13-G23 -> 13020.841 | H25: =H13-H23 -> 4569.6714 | I25: =I13-I23 -> 9346.4591 | ... M25: =M13-M23 -> 4484.4955 | N25: =SUM(B25:M25) -> 106532
B27: You should be able to copy from average to high and low and then just make some modifications
A28: HIGH DEMAND
A29: Month | B29: =B4 -> 44927 | C29: =C4 -> 44958 | D29: =D4 -> 44986 | E29: =E4 -> 45017 | F29: =F4 -> 45047 | G29: =G4 -> 45078 | H29: =H4 -> 45108 | I29: =I4 -> 45139 | ... M29: =M4 -> 45261 | N29: Yearly Total
A30: Demand | B30: =B5*1.22 -> 4234.5282 | C30: =C5*1.22 -> 4793.4275 | D30: =D5*1.22 -> 4947.152 | E30: =E5*1.22 -> 5559.5502 | F30: =F5*1.22 -> 6431.0214 | G30: =G5*1.22 -> 6439.1947 | H30: =H5*1.22 -> 4007.4904 | I30: =I5*1.22 -> 5381.9434 | ... M30: =M5*1.22 -> 9916.4465 | N30: =SUM(B30:M30) -> 72379.797
A31: satisfied demand | B31: =MIN(B30,$E$2) -> 4234.5282 | C31: =MIN(C30,$E$2) -> 4793.4275 | D31: =MIN(D30,$E$2) -> 4947.152 | E31: =MIN(E30,$E$2) -> 5280 | F31: =MIN(F30,$E$2) -> 5280 | G31: =MIN(G30,$E$2) -> 5280 | H31: =MIN(H30,$E$2) -> 4007.4904 | I31: =MIN(I30,$E$2) -> 5280 | ... M31: =MIN(M30,$E$2) -> 5280 | N31: =SUM(B31:M31) -> 60222.598
A32: Extra donuts(over) | B32: =IF($E$2>B30, $E$2-B30, 0) -> 1045.4718 | C32: =IF($E$2>C30, $E$2-C30, 0) -> 486.57254 | D32: =IF($E$2>D30, $E$2-D30, 0) -> 332.84805 | E32: =IF($E$2>E30, $E$2-E30, 0) -> 0 | F32: =IF($E$2>F30, $E$2-F30, 0) -> 0 | G32: =IF($E$2>G30, $E$2-G30, 0) -> 0 | H32: =IF($E$2>H30, $E$2-H30, 0) -> 1272.5096 | I32: =IF($E$2>I30, $E$2-I30, 0) -> 0 | ... M32: =IF($E$2>M30, $E$2-M30, 0) -> 0 | N32: =SUM(B32:M32) -> 3137.4021
A33: Unsatisfied customers (short) | B33: =IF(B30>$E$2, B30-$E$2, 0) -> 0 | C33: =IF(C30>$E$2, C30-$E$2, 0) -> 0 | D33: =IF(D30>$E$2, D30-$E$2, 0) -> 0 | E33: =IF(E30>$E$2, E30-$E$2, 0) -> 279.55024 | F33: =IF(F30>$E$2, F30-$E$2, 0) -> 1151.0214 | G33: =IF(G30>$E$2, G30-$E$2, 0) -> 1159.1947 | H33: =IF(H30>$E$2, H30-$E$2, 0) -> 0 | I33: =IF(I30>$E$2, I30-$E$2, 0) -> 101.94342 | ... M33: =IF(M30>$E$2, M30-$E$2, 0) -> 4636.4465 | N33: =SUM(B33:M33) -> 12157.199
A34: Revenue
A35: coffee | B35: =B31*2.99 -> 12661.239 | C35: =C31*2.99 -> 14332.348 | D35: =D31*2.99 -> 14791.984 | E35: =E31*2.99 -> 15787.2 | F35: =F31*2.99 -> 15787.2 | G35: =G31*2.99 -> 15787.2 | H35: =H31*2.99 -> 11982.396 | I35: =I31*2.99 -> 15787.2 | ... M35: =M31*2.99 -> 15787.2 | N35: =SUM(B35:M35) -> 180065.57
A36: donut | B36: =B31*2.5 -> 10586.32 | C36: =C31*2.5 -> 11983.569 | D36: =D31*2.5 -> 12367.88 | E36: =E31*2.5 -> 13200 | F36: =F31*2.5 -> 13200 | G36: =G31*2.5 -> 13200 | H36: =H31*2.5 -> 10018.726 | I36: =I31*2.5 -> 13200 | ... M36: =M31*2.5 -> 13200 | N36: =SUM(B36:M36) -> 150556.49
A37: Revenue from day old sales | B37: =B32*$G$2 -> 1306.8398 | C37: =C32*$G$2 -> 608.21567 | D37: =D32*$G$2 -> 416.06006 | E37: =E32*$G$2 -> 0 | F37: =F32*$G$2 -> 0 | G37: =G32*$G$2 -> 0 | H37: =H32*$G$2 -> 1590.6371 | I37: =I32*$G$2 -> 0 | ... M37: =M32*$G$2 -> 0 | N37: =SUM(B37:M37) -> 3921.7526
A38: Total Revenue | B38: =SUM(B35:B37) -> 24554.399 | C38: =SUM(C35:C37) -> 26924.132 | D38: =SUM(D35:D37) -> 27575.924 | E38: =SUM(E35:E37) -> 28987.2 | F38: =SUM(F35:F37) -> 28987.2 | G38: =SUM(G35:G37) -> 28987.2 | H38: =SUM(H35:H37) -> 23591.759 | I38: =SUM(I35:I37) -> 28987.2 | ... M38: =SUM(M35:M37) -> 28987.2 | N38: =SUM(B38:M38) -> 334543.82
A39: Expenses
A40: Fixed Expenses | B40: =5800+4350 -> 10150 | C40: =5800+4350 -> 10150 | D40: =5800+4350 -> 10150 | E40: =5800+4350 -> 10150 | F40: =5800+4350 -> 10150 | G40: =5800+4350 -> 10150 | H40: =5800+4350 -> 10150 | I40: =5800+4350 -> 10150 | ... M40: =5800+4350 -> 10150 | N40: =SUM(B40:M40) -> 121800
A41: Total Fixed Expense | B41: =5800+4350 -> 10150 | C41: =5800+4350 -> 10150 | D41: =5800+4350 -> 10150 | E41: =5800+4350 -> 10150 | F41: =5800+4350 -> 10150 | G41: =5800+4350 -> 10150 | H41: =5800+4350 -> 10150 | I41: =5800+4350 -> 10150 | ... M41: =5800+4350 -> 10150 | N41: =SUM(B41:M41) -> 121800
A43: Variable Expenses
A44: Coffee Variable expense | B44: =$E$2*0.5 -> 2640 | C44: =$E$2*0.5 -> 2640 | D44: =$E$2*0.5 -> 2640 | E44: =$E$2*0.5 -> 2640 | F44: =$E$2*0.5 -> 2640 | G44: =$E$2*0.5 -> 2640 | H44: =$E$2*0.5 -> 2640 | I44: =$E$2*0.5 -> 2640 | ... M44: =$E$2*0.5 -> 2640 | N44: =SUM(B44:M44) -> 31680
...

Sheet Expected Values Pt4
A1: Remember that we use profits to fill in payoff tables like the ones we forecasted in the previous sheets. It would help if you filled in the table in C5:E7 and referenced those values to the other tables below. Use the probabilities found in Financial Information B42:44 for the regret tables | B1: PAYOFF TABLE | C1: Reminder: Format Cells to show 2 decimal places
I2: Fill in the space below for each method solved under each Decision Alternative. This is just a summary of the results on the left.
C3: State of Nature | H3: Summary of Results | I3: Methods
B4: Decision Alternatives | C4: Low | D4: Average | E4: High | H4: =B4 -> Decision Alternatives | I4: Maximin | J4: MaxiMax | K4: Laplace | L4: MinMax regret | M4: EVUII | N4: EOL
B5: CURRENT OPERATIONS | C5: 83444.24 | D5: 105161.52 | E5: 97614.786 | H5: CURRENT OPERATIONS
B6: FRANCHISE | C6: 68529.967 | D6: 106532 | E6: 106576.22 | H6: FRANCHISE
B7: FOOD TRUCK | C7: 60155.663 | D7: 102562.25 | E7: 110717.36 | H7: FOOD TRUCK
B9: DM UNDER IGNORANCE | H9: Kiana should choose to:
B10: Maximin
C11: State of Nature
B12: Decision Alternatives | C12: Low | D12: Average | E12: High | F12: min | G12: max
B13: CURRENT OPERATIONS | C13: =C5 -> 83444.24 | D13: =D5 -> 105161.52 | E13: =E5 -> 97614.786 | F13: =MIN(C13:E13) -> 83444.24 | G13: =MAX(F13:F15) -> 83444.24
B14: FRANCHISE | C14: =C6 -> 68529.967 | D14: =D6 -> 106532 | E14: =E6 -> 106576.22 | F14: =MIN(C14:E14) -> 68529.967
B15: FOOD TRUCK | C15: =C7 -> 60155.663 | D15: =D7 -> 102562.25 | E15: =E7 -> 110717.36 | F15: =MIN(C15:E15) -> 60155.663
B17: Maximax
C18: State of Nature
B19: Decision Alternatives | C19: Low | D19: Average | E19: High | F19: max | G19: max
B20: CURRENT OPERATIONS | C20: =C5 -> 83444.24 | D20: =D5 -> 105161.52 | E20: =E5 -> 97614.786 | F20: =MAX(C20:E20) -> 105161.52 | G20: =MAX(F20:F22) -> 110717.36
B21: FRANCHISE | C21: =C6 -> 68529.967 | D21: =D6 -> 106532 | E21: =E6 -> 106576.22 | F21: =MAX(C21:E21) -> 106576.22
B22: FOOD TRUCK | C22: =C7 -> 60155.663 | D22: =D7 -> 102562.25 | E22: =E7 -> 110717.36 | F22: =MAX(C22:E22) -> 110717.36
B24: Laplace
C25: State of Nature
B26: Decision Alternatives | C26: Low | D26: Average | E26: High | F26: avg` | G26: max
B27: CURRENT OPERATIONS | C27: =C20 -> 83444.24 | D27: =D20 -> 105161.52 | E27: =E20 -> 97614.786 | F27: =AVERAGE(C27:E27) -> 95406.848 | G27: =MAX(F27:F29) -> 95406.848
B28: FRANCHISE | C28: =C21 -> 68529.967 | D28: =D21 -> 106532 | E28: =E21 -> 106576.22 | F28: =AVERAGE(C28:E28) -> 93879.395
B29: FOOD TRUCK | C29: =C22 -> 60155.663 | D29: =D22 -> 102562.25 | E29: =E22 -> 110717.36 | F29: =AVERAGE(C29:E29) -> 91145.09
B31: Minimax Regret
B32: Regret table | C32: State of Nature
B33: Decision Alternatives | C33: Low | D33: Average | E33: High | F33: max | G33: min
B34: CURRENT OPERATIONS | C34: =$C$27-C27 -> 0 | D34: =$D$28-D27 -> 1370.4821 | E34: =$E$29-E27 -> 13102.573 | F34: =MAX(C34:E34) -> 13102.573 | G34: =MIN(F34:F36) -> 13102.573
B35: FRANCHISE | C35: =$C$27-C28 -> 14914.273 | D35: =$D$28-D28 -> 0 | E35: =$E$29-E28 -> 4141.14 | F35: =MAX(C35:E35) -> 14914.273
B36: FOOD TRUCK | C36: =$C$27-C29 -> 23288.577 | D36: =$D$28-D29 -> 3969.7527 | E36: =$E$29-E29 -> 0 | F36: =MAX(C36:E36) -> 23288.577
B38: DM UNDER RISK
B39: EVUII
C40: State of Nature
B41: Decision Alternatives | C41: Low | D41: Average | E41: High
B42: Probability | C42: 0.33 | D42: 0.33 | E42: 0.33
B43: CURRENT OPERATIONS | C43: 83444.24 | D43: 105161.52 | E43: 97614.786 | F43: =(0.2*C43)+(0.55*D43)+(0.25*E43) -> 98931.379 | G43: =MAX(F43:F45) -> 98942.648
B44: FRANCHISE | C44: 68529.967 | D44: 106532 | E44: 106576.22 | F44: =(0.2*C44)+(0.55*D44)+(0.25*E44) -> 98942.648
B45: FOOD TRUCK | C45: 60155.663 | D45: 102562.25 | E45: 110717.36 | F45: =(0.2*C45)+(0.55*D45)+(0.25*E45) -> 96119.708
...

Sheet Food Truck Demand
A1: Month | B1: Demand | C1: Hours operating/week | D1: Event location | E1: office location | H1: Demand is based off multiple regression
A2: 44470 | B2: 3634 | C2: 30 | D2: 1 | E2: 0 | H2: Use the data to the left from 10/2021 till 1/2023 to create a regression model
A3: 44501 | B3: 4550 | C3: 40 | D3: 0 | E3: 1 | H3: Use the model and the data in the blue box to create the demand for 2023
A4: 44531 | B4: 5330 | C4: 55 | D4: 1 | E4: 0
A5: 44562 | B5: 3100 | C5: 30 | D5: 0 | E5: 1 | H5: Event and office location are dummy variables.
A6: 44593 | B6: 2999 | C6: 30 | D6: 0 | E6: 1 | H6: Since these are the only 2 possible locations. This means that if they aren't at an Event location, they will be at an office location.
A7: 44621 | B7: 3051 | C7: 35 | D7: 1 | E7: 0 | H7: Therefore you only need to use 1 ( such as just the Event column) in the Regression, since by default a 0 in the event column means they are at an office location.
A8: 44652 | B8: 3753 | C8: 35 | D8: 0 | E8: 1
A9: 44682 | B9: 3709 | C9: 35 | D9: 0 | E9: 1
A10: 44713 | B10: 3930 | C10: 40 | D10: 1 | E10: 0
A11: 44743 | B11: 2949 | C11: 40 | D11: 0 | E11: 1
A12: 44774 | B12: 3348 | C12: 45 | D12: 0 | E12: 1
A13: 44805 | B13: 3400 | C13: 40 | D13: 0 | E13: 1
A14: 44835 | B14: 4400 | C14: 55 | D14: 1 | E14: 0
A15: 44866 | B15: 5079 | C15: 55 | D15: 1 | E15: 0
A16: 44896 | B16: 6087 | C16: 60 | D16: 1 | E16: 0
A17: 44927 | B17: =$I$38+($I$39*C17)+($I$40*D17) -> 1949.7956 | C17: 15 | D17: 0 | E17: 1 | H17: This Blue box represent the variables to use in the regression equation to predict the demand for 2023.
A18: 44958 | B18: =$I$38+($I$39*C18)+($I$40*D18) -> 2298.6423 | C18: 20 | D18: 0 | E18: 1
A19: 44986 | B19: =$I$38+($I$39*C19)+($I$40*D19) -> 2298.6423 | C19: 20 | D19: 0 | E19: 1
A20: 45017 | B20: =$I$38+($I$39*C20)+($I$40*D20) -> 2647.4891 | C20: 25 | D20: 0 | E20: 1
A21: 45047 | B21: =$I$38+($I$39*C21)+($I$40*D21) -> 2647.4891 | C21: 25 | D21: 0 | E21: 1
A22: 45078 | B22: =$I$38+($I$39*C22)+($I$40*D22) -> 3654.3723 | C22: 35 | D22: 1 | E22: 0 | H22: SUMMARY OUTPUT
A23: 45108 | B23: =$I$38+($I$39*C23)+($I$40*D23) -> 3654.3723 | C23: 35 | D23: 1 | E23: 0
A24: 45139 | B24: =$I$38+($I$39*C24)+($I$40*D24) -> 2647.4891 | C24: 25 | D24: 0 | E24: 1 | H24: Regression Statistics
A25: 45170 | B25: =$I$38+($I$39*C25)+($I$40*D25) -> 2996.3358 | C25: 30 | D25: 0 | E25: 1 | H25: Multiple R | I25: 0.84434541
A26: 45200 | B26: =$I$38+($I$39*C26)+($I$40*D26) -> 4003.219 | C26: 40 | D26: 1 | E26: 0 | H26: R Square | I26: 0.71291916
A27: 45231 | B27: =$I$38+($I$39*C27)+($I$40*D27) -> 4003.219 | C27: 40 | D27: 1 | E27: 0 | H27: Adjusted R Square | I27: 0.66507236
A28: 45261 | B28: =$I$38+($I$39*C28)+($I$40*D28) -> 4352.0657 | C28: 45 | D28: 1 | E28: 0 | H28: Standard Error | I28: 549.18651
H29: Observations | I29: 15
H31: ANOVA
B32: =SUM(B17:B28) -> 37153.131 | I32: df | J32: SS | K32: MS | L32: F | M32: Significance F
H33: Regression | I33: 2 | J33: 8987875.7 | K33: 4493937.9 | L33: 14.900037 | M33: 0.0005597901
H34: Residual | I34: 12 | J34: 3619269.9 | K34: 301605.82
H35: Total | I35: 14 | J35: 12607146
I37: Coefficients | J37: Standard Error | K37: t Stat | L37: P-value | M37: Lower 95% | N37: Upper 95% | O37: Lower 95.0% | P37: Upper 95.0%
H38: Intercept | I38: 903.25547 | J38: 657.37506 | K38: 1.3740337 | L38: 0.19455225 | M38: -529.04173 | N38: 2335.5527 | O38: -529.04173 | P38: 2335.5527
H39: Hours operating/week | I39: 69.769343 | J39: 17.031744 | K39: 4.0964297 | L39: 0.0014817974 | M39: 32.66036 | N39: 106.87833 | O39: 32.66036 | P39: 106.87833
H40: Event location | I40: 309.18978 | J40: 333.72162 | K40: 0.92649011 | L40: 0.37245001 | M40: -417.92717 | N40: 1036.3067 | O40: -417.92717 | P40: 1036.3067
I43: Regression Equation
I44: y = 69.76934307x1+309.189781x2+

Sheet Food Truck  Pt 4
A1: Food Truck | B1: Reminder: Format Cells to show 2 decimal places | E1: MAKE to Order
A2: Part 4
A3: AVERAGE DEMAND
A4: Month | B4: 44927 | C4: 44958 | D4: 44986 | E4: 45017 | F4: 45047 | G4: 45078 | H4: 45108 | I4: 45139 | J4: 45170 | K4: 45200 | L4: 45231 | M4: 45261 | N4: Yearly Total
A5: Demand | B5: ='Food Truck Demand'!B17 -> 1949.7956 | C5: ='Food Truck Demand'!B18 -> 2298.6423 | D5: ='Food Truck Demand'!B19 -> 2298.6423 | E5: ='Food Truck Demand'!B20 -> 2647.4891 | F5: ='Food Truck Demand'!B21 -> 2647.4891 | G5: ='Food Truck Demand'!B22 -> 3654.3723 | H5: ='Food Truck Demand'!B23 -> 3654.3723 | I5: ='Food Truck Demand'!B24 -> 2647.4891 | J5: ='Food Truck Demand'!B25 -> 2996.3358 | K5: ='Food Truck Demand'!B26 -> 4003.219 | L5: ='Food Truck Demand'!B27 -> 4003.219 | M5: ='Food Truck Demand'!B28 -> 4352.0657 | N5: =SUM(B5:M5) -> 37153.131
A6: satisfied demand | B6: =B5 -> 1949.7956 | C6: =C5 -> 2298.6423 | D6: =D5 -> 2298.6423 | E6: =E5 -> 2647.4891 | F6: =F5 -> 2647.4891 | G6: =G5 -> 3654.3723 | H6: =H5 -> 3654.3723 | I6: =I5 -> 2647.4891 | ... M6: =M5 -> 4352.0657 | N6: =SUM(B6:M6) -> 37153.131
A7: Extra donuts(over) | B7: 0 | C7: 0 | D7: 0 | E7: 0 | F7: 0 | G7: 0 | H7: 0 | I7: 0 | J7: 0 | K7: 0 | L7: 0 | M7: 0 | N7: =SUM(B7:M7) -> 0
A8: Unsatisfied customers (short) | B8: 0 | C8: 0 | D8: 0 | E8: 0 | F8: 0 | G8: 0 | H8: 0 | I8: 0 | J8: 0 | K8: 0 | L8: 0 | M8: 0 | N8: =SUM(B8:M8) -> 0
A9: Revenue
A10: coffee | B10: =B5*2.99 -> 5829.8889 | C10: =C5*2.99 -> 6872.9406 | D10: =D5*2.99 -> 6872.9406 | E10: =E5*2.99 -> 7915.9923 | F10: =F5*2.99 -> 7915.9923 | G10: =G5*2.99 -> 10926.573 | H10: =H5*2.99 -> 10926.573 | I10: =I5*2.99 -> 7915.9923 | ... M10: =M5*2.99 -> 13012.676 | N10: =SUM(B10:M10) -> 111087.86
A11: donut | B11: =B5*2.5 -> 4874.4891 | C11: =C5*2.5 -> 5746.6058 | D11: =D5*2.5 -> 5746.6058 | E11: =E5*2.5 -> 6618.7226 | F11: =F5*2.5 -> 6618.7226 | G11: =G5*2.5 -> 9135.9307 | H11: =H5*2.5 -> 9135.9307 | I11: =I5*2.5 -> 6618.7226 | ... M11: =M5*2.5 -> 10880.164 | N11: =SUM(B11:M11) -> 92882.828
A12: Revenue from day old sales | B12: 0 | C12: 0 | D12: 0 | E12: 0 | F12: 0 | G12: 0 | H12: 0 | I12: 0 | J12: 0 | K12: 0 | L12: 0 | M12: 0 | N12: =SUM(B12:M12) -> 0
A13: Total Revenue | B13: =SUM(B10:B12) -> 10704.378 | C13: =SUM(C10:C12) -> 12619.546 | D13: =SUM(D10:D12) -> 12619.546 | E13: =SUM(E10:E12) -> 14534.715 | F13: =SUM(F10:F12) -> 14534.715 | G13: =SUM(G10:G12) -> 20062.504 | H13: =SUM(H10:H12) -> 20062.504 | I13: =SUM(I10:I12) -> 14534.715 | ... M13: =SUM(M10:M12) -> 23892.841 | N13: =SUM(B13:M13) -> 203970.69
A14: Expenses
A15: Fixed Expenses | B15: 5045 | C15: 5045 | D15: 5045 | E15: 5045 | F15: 5045 | G15: 5045 | H15: 5045 | I15: 5045 | J15: 5045 | K15: 5045 | L15: 5045 | M15: 5045 | N15: =SUM(B15:M15) -> 60540
A16: Total Fixed Expense | B16: 5045 | C16: 5045 | D16: 5045 | E16: 5045 | F16: 5045 | G16: 5045 | H16: 5045 | I16: 5045 | J16: 5045 | K16: 5045 | L16: 5045 | M16: 5045 | N16: =SUM(B16:M16) -> 60540
A18: Variable Expenses
A19: Coffee Variable expense | B19: =B5*0.5 -> 974.89781 | C19: =C5*0.5 -> 1149.3212 | D19: =D5*0.5 -> 1149.3212 | E19: =E5*0.5 -> 1323.7445 | F19: =F5*0.5 -> 1323.7445 | G19: =G5*0.5 -> 1827.1861 | H19: =H5*0.5 -> 1827.1861 | I19: =I5*0.5 -> 1323.7445 | ... M19: =M5*0.5 -> 2176.0328 | N19: =SUM(B19:M19) -> 18576.566
A20: Donut Variable expense | B20: =B5*0.6 -> 1169.8774 | C20: =C5*0.6 -> 1379.1854 | D20: =D5*0.6 -> 1379.1854 | E20: =E5*0.6 -> 1588.4934 | F20: =F5*0.6 -> 1588.4934 | G20: =G5*0.6 -> 2192.6234 | H20: =H5*0.6 -> 2192.6234 | I20: =I5*0.6 -> 1588.4934 | ... M20: =M5*0.6 -> 2611.2394 | N20: =SUM(B20:M20) -> 22291.879
A21: Total Variable Expenses | B21: =SUM(B19:B20) -> 2144.7752 | C21: =SUM(C19:C20) -> 2528.5066 | D21: =SUM(D19:D20) -> 2528.5066 | E21: =SUM(E19:E20) -> 2912.238 | F21: =SUM(F19:F20) -> 2912.238 | G21: =SUM(G19:G20) -> 4019.8095 | H21: =SUM(H19:H20) -> 4019.8095 | I21: =SUM(I19:I20) -> 2912.238 | ... M21: =SUM(M19:M20) -> 4787.2723 | N21: =SUM(B21:M21) -> 40868.445
A22: Expenses: due to lost sales | B22: 0 | C22: 0 | D22: 0 | E22: 0 | F22: 0 | G22: 0 | H22: 0 | I22: 0 | J22: 0 | K22: 0 | L22: 0 | M22: 0 | N22: =SUM(B22:M22) -> 0
A23: Total Expenses | B23: =SUM(B16,B21,B22) -> 7189.7752 | C23: =SUM(C16,C21,C22) -> 7573.5066 | D23: =SUM(D16,D21,D22) -> 7573.5066 | E23: =SUM(E16,E21,E22) -> 7957.238 | F23: =SUM(F16,F21,F22) -> 7957.238 | G23: =SUM(G16,G21,G22) -> 9064.8095 | H23: =SUM(H16,H21,H22) -> 9064.8095 | I23: =SUM(I16,I21,I22) -> 7957.238 | ... M23: =SUM(M16,M21,M22) -> 9832.2723 | N23: =SUM(B23:M23) -> 101408.44
A25: Profit Donuts and Coffee | B25: =B13-B23 -> 3514.6028 | C25: =C13-C23 -> 5046.0399 | D25: =D13-D23 -> 5046.0399 | E25: =E13-E23 -> 6577.4769 | F25: =F13-F23 -> 6577.4769 | G25: =G13-G23 -> 10997.694 | H25: =H13-H23 -> 10997.694 | I25: =I13-I23 -> 6577.4769 | ... M25: =M13-M23 -> 14060.568 | N25: =SUM(B25:M25) -> 102562.25
B27: You should be able to copy from average to high and low and then just make some modifications
A28: HIGH DEMAND
A29: Month | B29: =B4 -> 44927 | C29: =C4 -> 44958 | D29: =D4 -> 44986 | E29: =E4 -> 45017 | F29: =F4 -> 45047 | G29: =G4 -> 45078 | H29: =H4 -> 45108 | I29: =I4 -> 45139 | ... M29: =M4 -> 45261 | N29: Yearly Total
A30: Demand | B30: =B5*1.05 -> 2047.2854 | C30: =C5*1.05 -> 2413.5745 | D30: =D5*1.05 -> 2413.5745 | E30: =E5*1.05 -> 2779.8635 | F30: =F5*1.05 -> 2779.8635 | G30: =G5*1.05 -> 3837.0909 | H30: =H5*1.05 -> 3837.0909 | I30: =I5*1.05 -> 2779.8635 | ... M30: =M5*1.05 -> 4569.669 | N30: =SUM(B30:M30) -> 39010.788
A31: satisfied demand | B31: =B30 -> 2047.2854 | C31: =C30 -> 2413.5745 | D31: =D30 -> 2413.5745 | E31: =E30 -> 2779.8635 | F31: =F30 -> 2779.8635 | G31: =G30 -> 3837.0909 | H31: =H30 -> 3837.0909 | I31: =I30 -> 2779.8635 | ... M31: =M30 -> 4569.669 | N31: =SUM(B31:M31) -> 39010.788
A32: Extra donuts(over) | B32: 0 | C32: 0 | D32: 0 | E32: 0 | F32: 0 | G32: 0 | H32: 0 | I32: 0 | J32: 0 | K32: 0 | L32: 0 | M32: 0 | N32: =SUM(B32:M32) -> 0
A33: Unsatisfied customers (short) | B33: 0 | C33: 0 | D33: 0 | E33: 0 | F33: 0 | G33: 0 | H33: 0 | I33: 0 | J33: 0 | K33: 0 | L33: 0 | M33: 0 | N33: =SUM(B33:M33) -> 0
A34: Revenue
A35: coffee | B35: =B30*2.99 -> 6121.3834 | C35: =C30*2.99 -> 7216.5876 | D35: =D30*2.99 -> 7216.5876 | E35: =E30*2.99 -> 8311.7919 | F35: =F30*2.99 -> 8311.7919 | G35: =G30*2.99 -> 11472.902 | H35: =H30*2.99 -> 11472.902 | I35: =I30*2.99 -> 8311.7919 | ... M35: =M30*2.99 -> 13663.31 | N35: =SUM(B35:M35) -> 116642.26
A36: donut | B36: =B30*2.5 -> 5118.2135 | C36: =C30*2.5 -> 6033.9361 | D36: =D30*2.5 -> 6033.9361 | E36: =E30*2.5 -> 6949.6588 | F36: =F30*2.5 -> 6949.6588 | G36: =G30*2.5 -> 9592.7272 | H36: =H30*2.5 -> 9592.7272 | I36: =I30*2.5 -> 6949.6588 | ... M36: =M30*2.5 -> 11424.172 | N36: =SUM(B36:M36) -> 97526.97
A37: Revenue from day old sales | B37: 0 | C37: 0 | D37: 0 | E37: 0 | F37: 0 | G37: 0 | H37: 0 | I37: 0 | J37: 0 | K37: 0 | L37: 0 | M37: 0 | N37: =SUM(B37:M37) -> 0
A38: Total Revenue | B38: =SUM(B35:B37) -> 11239.597 | C38: =SUM(C35:C37) -> 13250.524 | D38: =SUM(D35:D37) -> 13250.524 | E38: =SUM(E35:E37) -> 15261.451 | F38: =SUM(F35:F37) -> 15261.451 | G38: =SUM(G35:G37) -> 21065.629 | H38: =SUM(H35:H37) -> 21065.629 | I38: =SUM(I35:I37) -> 15261.451 | ... M38: =SUM(M35:M37) -> 25087.483 | N38: =SUM(B38:M38) -> 214169.23
A39: Expenses
A40: Fixed Expenses | B40: 5045 | C40: 5045 | D40: 5045 | E40: 5045 | F40: 5045 | G40: 5045 | H40: 5045 | I40: 5045 | J40: 5045 | K40: 5045 | L40: 5045 | M40: 5045 | N40: =SUM(B40:M40) -> 60540
A41: Total Fixed Expense | B41: 5045 | C41: 5045 | D41: 5045 | E41: 5045 | F41: 5045 | G41: 5045 | H41: 5045 | I41: 5045 | J41: 5045 | K41: 5045 | L41: 5045 | M41: 5045 | N41: =SUM(B41:M41) -> 60540
A43: Variable Expenses
A44: Coffee Variable expense | B44: =B30*0.5 -> 1023.6427 | C44: =C30*0.5 -> 1206.7872 | D44: =D30*0.5 -> 1206.7872 | E44: =E30*0.5 -> 1389.9318 | F44: =F30*0.5 -> 1389.9318 | G44: =G30*0.5 -> 1918.5454 | H44: =H30*0.5 -> 1918.5454 | I44: =I30*0.5 -> 1389.9318 | ... M44: =M30*0.5 -> 2284.8345 | N44: =SUM(B44:M44) -> 19505.394
...

Sheet Financial information  FT
A1: Donut Information for Food Truck
A2: Based on the below data, create the profit model for Donuts to Go.
A3: Assume that each customer will buy one donut and one cup of coffee
C5: new | D5: Drop Production since flexible hours and limited storage space
A6: Item | B6: Profit Model label | C6: Expense/revenue FT
A7: Revenue: Cup of Coffee | B7: Rev: Coffee | C7: 2.99
A8: Revenue: Donut | B8: Rev: Donut | C8: 2.5
A9: Donut ingredients per donunt) | B9: Variable Expense donut | C9: 0.5
A10: paper products: napkins, plates etc per Donut | B10: Variable Expense donut | C10: 0.1
A11: Insurance | B11: Fixed Expense | C11: 150
A12: Maintenance & Repairs to equipment | B12: Fixed Expense | C12: 300
A13: Marketing & Promotion: Advertising | B13: Fixed Expense | C13: 0 | D13: No advertising, Friend doing locations on Insta and Facebook
A14: Coffee | B14: Variable Expense coffee | C14: 0.35
A15: Coffee cups | B15: Variable Expense coffee | C15: 0.15
A16: Payroll: Wages (Owner/ Manager) | B16: Fixed Expense | C16: 2400
A17: Payroll: Wages (per Employees) | B17: Fixed Expense | C17: 0 | D17: No other employees
A18: Donut and Coffee equipment rent | B18: Fixed Expense | C18: 0
A19: Professional Fees: Accounting | B19: Fixed Expense | C19: 50
A20: Professional Fees: Legal | B20: Fixed Expense | C20: 25
A21: Powdered and Liquid Beverages | B21: Fixed Expense | C21: 0
A22: Rent | B22: Fixed Expense | C22: 2120 | D22: No rent instead payment for lease on Food Truck.
A23: Supplies: Office | B23: Fixed Expense | C23: 0
A24: Utilities | B24: Fixed Expense | C24: 0
A30: Additional Data
A31: Food Truck
A32: Monthly Production | B32: make to order
A33: Lost Sales
A34: Day old revenue
A35: High demand, % above Average | B35: 0.05
A36: Low Demand, % below average | B36: 0.26
A62: Total
